Workbook

Sheet No of Courses
A1: AGRI | B1: PROFESSIONAL ELECTIVE I | C1: 22AG040 | D1: TECHNOLOGY OF SEED PROCESSING | E1: 26 | F1: =IFERROR(__xludf.DUMMYFUNCTION("counta(IFNA(FILTER('Consolidated Sheet'!D:D, 'Consolidated Sheet'!A:A=A1, 'Consolidated Sheet'!D:D=C1)))"),1.0) -> 1
A2: AIDS | B2: PROFESSIONAL ELECTIVE I | C2: 22AI043 | D2: PYTHON FOR DATA SCIENCE | E2: 134 | F2: =IFERROR(__xludf.DUMMYFUNCTION("counta(IFNA(FILTER('Consolidated Sheet'!D:D, 'Consolidated Sheet'!A:A=A2, 'Consolidated Sheet'!D:D=C2)))"),2.0) -> 2
A3: AIDS | B3: PROFESSIONAL ELECTIVE I | C3: 22AI002 | D3: UI AND UX DESIGN | E3: 128 | F3: =IFERROR(__xludf.DUMMYFUNCTION("counta(IFNA(FILTER('Consolidated Sheet'!D:D, 'Consolidated Sheet'!A:A=A3, 'Consolidated Sheet'!D:D=C3)))"),2.0) -> 2
A4: AIML | B4: PROFESSIONAL ELECTIVE I | C4: 22AM002 | D4: UI AND UX DESIGN | E4: 54 | F4: =IFERROR(__xludf.DUMMYFUNCTION("counta(IFNA(FILTER('Consolidated Sheet'!D:D, 'Consolidated Sheet'!A:A=A4, 'Consolidated Sheet'!D:D=C4)))"),1.0) -> 1
A5: AIML | B5: PROFESSIONAL ELECTIVE I | C5: 22AM027 | D5: MOBILE AND WEB APPLICATION | E5: 72 | F5: =IFERROR(__xludf.DUMMYFUNCTION("counta(IFNA(FILTER('Consolidated Sheet'!D:D, 'Consolidated Sheet'!A:A=A5, 'Consolidated Sheet'!D:D=C5)))"),2.0) -> 2
A6: BT | B6: PROFESSIONAL ELECTIVE I | C6: 22BT012 | D6: BIODIVERSITY AND AGROFORESTRY | E6: 26 | F6: =IFERROR(__xludf.DUMMYFUNCTION("counta(IFNA(FILTER('Consolidated Sheet'!D:D, 'Consolidated Sheet'!A:A=A6, 'Consolidated Sheet'!D:D=C6)))"),1.0) -> 1
A7: BT | B7: PROFESSIONAL ELECTIVE I | C7: 22BT003 | D7: ENVIRONMENTAL BIOTECHNOLOGY | E7: 97 | F7: =IFERROR(__xludf.DUMMYFUNCTION("counta(IFNA(FILTER('Consolidated Sheet'!D:D, 'Consolidated Sheet'!A:A=A7, 'Consolidated Sheet'!D:D=C7)))"),2.0) -> 2
A8: CSE | B8: PROFESSIONAL ELECTIVE I | C8: 22CS008 | D8: UI AND UX DESIGN | E8: 343 | F8: =IFERROR(__xludf.DUMMYFUNCTION("counta(IFNA(FILTER('Consolidated Sheet'!D:D, 'Consolidated Sheet'!A:A=A8, 'Consolidated Sheet'!D:D=C8)))"),6.0) -> 6
A9: CSE | B9: PROFESSIONAL ELECTIVE I | C9: 22CS007 | D9: AGILE SOFTWARE DEVELOPMENT | E9: 39 | F9: =IFERROR(__xludf.DUMMYFUNCTION("counta(IFNA(FILTER('Consolidated Sheet'!D:D, 'Consolidated Sheet'!A:A=A9, 'Consolidated Sheet'!D:D=C9)))"),1.0) -> 1
A10: CSE | B10: PROFESSIONAL ELECTIVE I | C10: 22CS039 | D10: INTERNET OF THINGS | E10: 29 | F10: =IFERROR(__xludf.DUMMYFUNCTION("counta(IFNA(FILTER('Consolidated Sheet'!D:D, 'Consolidated Sheet'!A:A=A10, 'Consolidated Sheet'!D:D=C10)))"),1.0) -> 1
A11: CSBS | B11: PROFESSIONAL ELECTIVE I | C11: 22CB031 | D11: INTRODUCTION TO INNOVATION IP MANAGEMENT AND ENTREPRENEURSHIP | E11: 62 | F11: =IFERROR(__xludf.DUMMYFUNCTION("counta(IFNA(FILTER('Consolidated Sheet'!D:D, 'Consolidated Sheet'!A:A=A11, 'Consolidated Sheet'!D:D=C11)))"),1.0) -> 1
A12: EEE | B12: PROFESSIONAL ELECTIVE I | C12: 22EE007 | D12: ADVANCED POWER SEMICONDUCTOR DEVICES | E12: 95 | F12: =IFERROR(__xludf.DUMMYFUNCTION("counta(IFNA(FILTER('Consolidated Sheet'!D:D, 'Consolidated Sheet'!A:A=A12, 'Consolidated Sheet'!D:D=C12)))"),2.0) -> 2
A13: EEE | B13: PROFESSIONAL ELECTIVE I | C13: 22EE033 | D13: ILLUMINATION ENGINEERING | E13: 40 | F13: =IFERROR(__xludf.DUMMYFUNCTION("counta(IFNA(FILTER('Consolidated Sheet'!D:D, 'Consolidated Sheet'!A:A=A13, 'Consolidated Sheet'!D:D=C13)))"),1.0) -> 1
A14: ECE | B14: PROFESSIONAL ELECTIVE I | C14: 22EC001 | D14: ADVANCED PROCESSOR ARCHITECTURES | E14: 148 | F14: =IFERROR(__xludf.DUMMYFUNCTION("counta(IFNA(FILTER('Consolidated Sheet'!D:D, 'Consolidated Sheet'!A:A=A14, 'Consolidated Sheet'!D:D=C14)))"),3.0) -> 3
A15: ECE | B15: PROFESSIONAL ELECTIVE I | C15: 22EC040 | D15: PYTHON PROGRAMMING FOR AI AND ML | E15: 124 | F15: =IFERROR(__xludf.DUMMYFUNCTION("counta(IFNA(FILTER('Consolidated Sheet'!D:D, 'Consolidated Sheet'!A:A=A15, 'Consolidated Sheet'!D:D=C15)))"),2.0) -> 2
A16: EIE | B16: PROFESSIONAL ELECTIVE I | C16: 22EI014 | D16: ANALYTICAL INSTRUMENTS | E16: 63 | F16: =IFERROR(__xludf.DUMMYFUNCTION("counta(IFNA(FILTER('Consolidated Sheet'!D:D, 'Consolidated Sheet'!A:A=A16, 'Consolidated Sheet'!D:D=C16)))"),1.0) -> 1
A17: IT | B17: PROFESSIONAL ELECTIVE I | C17: 22IT007 | D17: AGILE SOFTWARE DEVELOPMENT | E17: 45 | F17: =IFERROR(__xludf.DUMMYFUNCTION("counta(IFNA(FILTER('Consolidated Sheet'!D:D, 'Consolidated Sheet'!A:A=A17, 'Consolidated Sheet'!D:D=C17)))"),1.0) -> 1
A18: IT | B18: PROFESSIONAL ELECTIVE I | C18: 22IT008 | D18: UI AND UX DESIGN | E18: 222 | F18: =IFERROR(__xludf.DUMMYFUNCTION("counta(IFNA(FILTER('Consolidated Sheet'!D:D, 'Consolidated Sheet'!A:A=A18, 'Consolidated Sheet'!D:D=C18)))"),4.0) -> 4
A19: MECH | B19: PROFESSIONAL ELECTIVE I | C19: 22ME001 | D19: CONCEPTS OF ENGINEERING DESIGN | E19: 68 | F19: =IFERROR(__xludf.DUMMYFUNCTION("counta(IFNA(FILTER('Consolidated Sheet'!D:D, 'Consolidated Sheet'!A:A=A19, 'Consolidated Sheet'!D:D=C19)))"),1.0) -> 1
A20: MTRS | B20: PROFESSIONAL ELECTIVE I | C20: 22MC015 | D20: AUTOMOTIVE INFOTRONICS | E20: 65 | F20: =IFERROR(__xludf.DUMMYFUNCTION("counta(IFNA(FILTER('Consolidated Sheet'!D:D, 'Consolidated Sheet'!A:A=A20, 'Consolidated Sheet'!D:D=C20)))"),0.0) -> 0
A21: AGRI | B21: ADD ON | C21: 22AG016 | D21: FOOD SAFETY MANAGEMENT SYSTEMS | E21: 22 | F21: =IFERROR(__xludf.DUMMYFUNCTION("counta(IFNA(FILTER('Consolidated Sheet'!D:D, 'Consolidated Sheet'!A:A=A21, 'Consolidated Sheet'!D:D=C21)))"),1.0) -> 1
A22: AGRI | B22: PROFESSIONAL ELECTIVE III | C22: 22AG008 | D22: GROUNDWATER, WELLS AND PUMPS | E22: 55 | F22: =IFERROR(__xludf.DUMMYFUNCTION("counta(IFNA(FILTER('Consolidated Sheet'!D:D, 'Consolidated Sheet'!A:A=A22, 'Consolidated Sheet'!D:D=C22)))"),1.0) -> 1
A23: AGRI | B23: PROFESSIONAL ELECTIVE IV | C23: 22AG001 | D23: HUMAN ENGINEERING AND SAFETY | E23: 55 | F23: =IFERROR(__xludf.DUMMYFUNCTION("counta(IFNA(FILTER('Consolidated Sheet'!D:D, 'Consolidated Sheet'!A:A=A23, 'Consolidated Sheet'!D:D=C23)))"),1.0) -> 1
A24: AGRI | B24: PROFESSIONAL ELECTIVE V | C24: 22AG017 | D24: EMERGING TECHNOLOGIES IN FOOD PROCESS ENGINEERING | E24: 40 | F24: =IFERROR(__xludf.DUMMYFUNCTION("counta(IFNA(FILTER('Consolidated Sheet'!D:D, 'Consolidated Sheet'!A:A=A24, 'Consolidated Sheet'!D:D=C24)))"),1.0) -> 1
A25: AIDS | B25: ADD ON | C25: 22AI029 | D25: QUANTUM COMPUTING | E25: 83 | F25: =IFERROR(__xludf.DUMMYFUNCTION("counta(IFNA(FILTER('Consolidated Sheet'!D:D, 'Consolidated Sheet'!A:A=A25, 'Consolidated Sheet'!D:D=C25)))"),2.0) -> 2
A26: AIDS | B26: PROFESSIONAL ELECTIVE III | C26: 22AI049 | D26: ETHICS IN DATA SCIENCE | E26: 130 | F26: =IFERROR(__xludf.DUMMYFUNCTION("counta(IFNA(FILTER('Consolidated Sheet'!D:D, 'Consolidated Sheet'!A:A=A26, 'Consolidated Sheet'!D:D=C26)))"),2.0) -> 2
A27: AIDS | B27: PROFESSIONAL ELECTIVE III | C27: 22AI020 | D27: REINFORCEMENT LEARNING | E27: 66 | F27: =IFERROR(__xludf.DUMMYFUNCTION("counta(IFNA(FILTER('Consolidated Sheet'!D:D, 'Consolidated Sheet'!A:A=A27, 'Consolidated Sheet'!D:D=C27)))"),1.0) -> 1
A28: AIDS | B28: PROFESSIONAL ELECTIVE IV | C28: 22AI032 | D28: RECOMMENDER SYSTEMS | E28: 86 | F28: =IFERROR(__xludf.DUMMYFUNCTION("counta(IFNA(FILTER('Consolidated Sheet'!D:D, 'Consolidated Sheet'!A:A=A28, 'Consolidated Sheet'!D:D=C28)))"),2.0) -> 2
A29: AIDS | B29: PROFESSIONAL ELECTIVE IV | C29: 22AI025 | D29: KNOWLEDGE ENGINEERING | E29: 110 | F29: =IFERROR(__xludf.DUMMYFUNCTION("counta(IFNA(FILTER('Consolidated Sheet'!D:D, 'Consolidated Sheet'!A:A=A29, 'Consolidated Sheet'!D:D=C29)))"),2.0) -> 2
A30: AIDS | B30: PROFESSIONAL ELECTIVE V | C30: 22AI035 | D30: BUSINESS ANALYTICS | E30: 63 | F30: =IFERROR(__xludf.DUMMYFUNCTION("counta(IFNA(FILTER('Consolidated Sheet'!D:D, 'Consolidated Sheet'!A:A=A30, 'Consolidated Sheet'!D:D=C30)))"),1.0) -> 1
A31: AIDS | B31: PROFESSIONAL ELECTIVE V | C31: 22AI036 | D31: DIGITAL MARKETING AND MANAGEMENT | E31: 42 | F31: =IFERROR(__xludf.DUMMYFUNCTION("counta(IFNA(FILTER('Consolidated Sheet'!D:D, 'Consolidated Sheet'!A:A=A31, 'Consolidated Sheet'!D:D=C31)))"),1.0) -> 1
A32: AIML | B32: ADD ON | C32: 22AM006 | D32: DEVOPS | E32: 64 | F32: =IFERROR(__xludf.DUMMYFUNCTION("counta(IFNA(FILTER('Consolidated Sheet'!D:D, 'Consolidated Sheet'!A:A=A32, 'Consolidated Sheet'!D:D=C32)))"),1.0) -> 1
A33: AIML | B33: PROFESSIONAL ELECTIVE III | C33: 22AM005 | D33: SOFTWARE TESTING AND AUTOMATION | E33: 125 | F33: =IFERROR(__xludf.DUMMYFUNCTION("counta(IFNA(FILTER('Consolidated Sheet'!D:D, 'Consolidated Sheet'!A:A=A33, 'Consolidated Sheet'!D:D=C33)))"),2.0) -> 2
A34: AIML | B34: PROFESSIONAL ELECTIVE IV | C34: 22AM014 | D34: MODERN CRYTOGRAPHY | E34: 125 | F34: =IFERROR(__xludf.DUMMYFUNCTION("counta(IFNA(FILTER('Consolidated Sheet'!D:D, 'Consolidated Sheet'!A:A=A34, 'Consolidated Sheet'!D:D=C34)))"),2.0) -> 2
A35: AIML | B35: PROFESSIONAL ELECTIVE V | C35: 22AM034 | D35: BUSINESS INTELLIGENCE | E35: 80 | F35: =IFERROR(__xludf.DUMMYFUNCTION("counta(IFNA(FILTER('Consolidated Sheet'!D:D, 'Consolidated Sheet'!A:A=A35, 'Consolidated Sheet'!D:D=C35)))"),2.0) -> 2
A36: BME | B36: ADD ON | C36: 22BM022 | D36: PROSTHETIC AND ORTHOTIC DEVICES | E36: 34 | F36: =IFERROR(__xludf.DUMMYFUNCTION("counta(IFNA(FILTER('Consolidated Sheet'!D:D, 'Consolidated Sheet'!A:A=A36, 'Consolidated Sheet'!D:D=C36)))"),1.0) -> 1
A37: BME | B37: OPEN ELECTIVE | C37: 22OBM01 | D37: Occupational Safety And Health In Public Health | E37: 198 | F37: =IFERROR(__xludf.DUMMYFUNCTION("counta(IFNA(FILTER('Consolidated Sheet'!D:D, 'Consolidated Sheet'!A:A=A37, 'Consolidated Sheet'!D:D=C37)))"),3.0) -> 3
A38: BME | B38: PROFESSIONAL ELECTIVE III | C38: 22BM005 | D38: ADVANCED MEDICAL IMAGE ANALYSIS | E38: 51 | F38: =IFERROR(__xludf.DUMMYFUNCTION("counta(IFNA(FILTER('Consolidated Sheet'!D:D, 'Consolidated Sheet'!A:A=A38, 'Consolidated Sheet'!D:D=C38)))"),1.0) -> 1
A39: BME | B39: PROFESSIONAL ELECTIVE IV | C39: 22BM031 | D39: MEDICAL OPTICS | E39: 51 | F39: =IFERROR(__xludf.DUMMYFUNCTION("counta(IFNA(FILTER('Consolidated Sheet'!D:D, 'Consolidated Sheet'!A:A=A39, 'Consolidated Sheet'!D:D=C39)))"),1.0) -> 1
A40: BME | B40: PROFESSIONAL ELECTIVE V | C40: 22BM011 | D40: REHABILITATION AND ROBOTICS ENGINEERING | E40: 36 | F40: =IFERROR(__xludf.DUMMYFUNCTION("counta(IFNA(FILTER('Consolidated Sheet'!D:D, 'Consolidated Sheet'!A:A=A40, 'Consolidated Sheet'!D:D=C40)))"),1.0) -> 1
...

Sheet Faculty Details
A1: S.No. | B1: Faculty ID | C1: Salutation | D1: Faculty Name | E1: Faculty Name | F1: Department Name | G1: Designation | H1: Email | I1: Theory Load | J1: Lab Load | K1: Theory Alloted | L1: Lab Alloted | M1: Working Status | N1: Theory load Status | O1: Lab Load Status | P1: Extra Theory Alloted | Q1: Extra Lab Alloted
A2: 1 | B2: AD10543 | C2: Mr | D2: RANJITH G | E2: =CONCATENATE(C2,".",D2) -> Mr.RANJITH G | F2: Artificial Intelligence and Data Science | G2: Assistant Professor Level III | H2: ranjith@bitsathy.ac.in | I2: =IFERROR(__xludf.DUMMYFUNCTION("QUERY(IMPORTRANGE(""https://docs.google.com/spreadsheets/d/1WWWnL0uEco2fCr2WvkXmt_9_Ox7wL_0CmzT8iuRp0aQ/edit?gid=1871111119#gid=1871111119"",""Details!A:X""),""SELECT Col8, Col9, Col10, Col11, Col12, Col13, Col14 WHERE Col2='""&B2&""'"",0)"),2.0) -> 2 | J2: =IFERROR(__xludf.DUMMYFUNCTION("""COMPUTED_VALUE"""),2.0) -> 2 | K2: =IFERROR(__xludf.DUMMYFUNCTION("""COMPUTED_VALUE"""),0.0) -> 0 | L2: =IFERROR(__xludf.DUMMYFUNCTION("""COMPUTED_VALUE"""),0.0) -> 0 | M2: =IFERROR(__xludf.DUMMYFUNCTION("""COMPUTED_VALUE"""),"Working") -> Working | N2: =IFERROR(__xludf.DUMMYFUNCTION("""COMPUTED_VALUE"""),"LOAD PENDING") -> LOAD PENDING | O2: =IFERROR(__xludf.DUMMYFUNCTION("""COMPUTED_VALUE"""),"LOAD PENDING") -> LOAD PENDING | P2: =IF(K2>I2,"Extra Theory Load Alloted","") | Q2: =IF(L2>J2,"Extra Lab Load Alloted","")
A3: 2 | B3: AD10628 | C3: Dr | D3: ARUN KUMAR R | E3: =CONCATENATE(C3,".",D3) -> Dr.ARUN KUMAR R | F3: Artificial Intelligence and Data Science | G3: Associate Professor | H3: arunkumarr@bitsathy.ac.in | I3: =IFERROR(__xludf.DUMMYFUNCTION("QUERY(IMPORTRANGE(""https://docs.google.com/spreadsheets/d/1WWWnL0uEco2fCr2WvkXmt_9_Ox7wL_0CmzT8iuRp0aQ/edit?gid=1871111119#gid=1871111119"",""Details!A:X""),""SELECT Col8, Col9, Col10, Col11, Col12, Col13, Col14 WHERE Col2='""&B3&""'"",0)"),2.0) -> 2 | J3: =IFERROR(__xludf.DUMMYFUNCTION("""COMPUTED_VALUE"""),2.0) -> 2 | K3: =IFERROR(__xludf.DUMMYFUNCTION("""COMPUTED_VALUE"""),1.0) -> 1 | L3: =IFERROR(__xludf.DUMMYFUNCTION("""COMPUTED_VALUE"""),0.0) -> 0 | M3: =IFERROR(__xludf.DUMMYFUNCTION("""COMPUTED_VALUE"""),"Working") -> Working | N3: =IFERROR(__xludf.DUMMYFUNCTION("""COMPUTED_VALUE"""),"LOAD PENDING") -> LOAD PENDING | O3: =IFERROR(__xludf.DUMMYFUNCTION("""COMPUTED_VALUE"""),"LOAD PENDING") -> LOAD PENDING | P3: =IF(K3>I3,"Extra Theory Load Alloted","") | Q3: =IF(L3>J3,"Extra Lab Load Alloted","")
A4: 3 | B4: AD10818 | C4: Dr | D4: ESWARAMOORTHY V | E4: =CONCATENATE(C4,".",D4) -> Dr.ESWARAMOORTHY V | F4: Artificial Intelligence and Data Science | G4: Professor | H4: eswaramoorthyv@bitsathy.ac.in | I4: =IFERROR(__xludf.DUMMYFUNCTION("QUERY(IMPORTRANGE(""https://docs.google.com/spreadsheets/d/1WWWnL0uEco2fCr2WvkXmt_9_Ox7wL_0CmzT8iuRp0aQ/edit?gid=1871111119#gid=1871111119"",""Details!A:X""),""SELECT Col8, Col9, Col10, Col11, Col12, Col13, Col14 WHERE Col2='""&B4&""'"",0)"),2.0) -> 2 | J4: =IFERROR(__xludf.DUMMYFUNCTION("""COMPUTED_VALUE"""),2.0) -> 2 | K4: =IFERROR(__xludf.DUMMYFUNCTION("""COMPUTED_VALUE"""),1.0) -> 1 | L4: =IFERROR(__xludf.DUMMYFUNCTION("""COMPUTED_VALUE"""),0.0) -> 0 | M4: =IFERROR(__xludf.DUMMYFUNCTION("""COMPUTED_VALUE"""),"Working") -> Working | N4: =IFERROR(__xludf.DUMMYFUNCTION("""COMPUTED_VALUE"""),"LOAD PENDING") -> LOAD PENDING | O4: =IFERROR(__xludf.DUMMYFUNCTION("""COMPUTED_VALUE"""),"LOAD PENDING") -> LOAD PENDING | P4: =IF(K4>I4,"Extra Theory Load Alloted","") | Q4: =IF(L4>J4,"Extra Lab Load Alloted","")
A5: 4 | B5: AD10838 | C5: Mrs | D5: NITHYAPRIYA S | E5: =CONCATENATE(C5,".",D5) -> Mrs.NITHYAPRIYA S | F5: Artificial Intelligence and Data Science | G5: Assistant Professor Level III | H5: nithyapriyas@bitsathy.ac.in | I5: =IFERROR(__xludf.DUMMYFUNCTION("QUERY(IMPORTRANGE(""https://docs.google.com/spreadsheets/d/1WWWnL0uEco2fCr2WvkXmt_9_Ox7wL_0CmzT8iuRp0aQ/edit?gid=1871111119#gid=1871111119"",""Details!A:X""),""SELECT Col8, Col9, Col10, Col11, Col12, Col13, Col14 WHERE Col2='""&B5&""'"",0)"),2.0) -> 2 | J5: =IFERROR(__xludf.DUMMYFUNCTION("""COMPUTED_VALUE"""),2.0) -> 2 | K5: =IFERROR(__xludf.DUMMYFUNCTION("""COMPUTED_VALUE"""),2.0) -> 2 | L5: =IFERROR(__xludf.DUMMYFUNCTION("""COMPUTED_VALUE"""),1.0) -> 1 | M5: =IFERROR(__xludf.DUMMYFUNCTION("""COMPUTED_VALUE"""),"Working") -> Working | N5: =IFERROR(__xludf.DUMMYFUNCTION("""COMPUTED_VALUE"""),"CORRECT") -> CORRECT | O5: =IFERROR(__xludf.DUMMYFUNCTION("""COMPUTED_VALUE"""),"LOAD PENDING") -> LOAD PENDING | P5: =IF(K5>I5,"Extra Theory Load Alloted","") | Q5: =IF(L5>J5,"Extra Lab Load Alloted","")
A6: 5 | B6: AD10928 | C6: Mrs | D6: NISHA DEVI K | E6: =CONCATENATE(C6,".",D6) -> Mrs.NISHA DEVI K | F6: Artificial Intelligence and Data Science | G6: Assistant Professor Level II | H6: nishadevik@bitsathy.ac.in | I6: =IFERROR(__xludf.DUMMYFUNCTION("QUERY(IMPORTRANGE(""https://docs.google.com/spreadsheets/d/1WWWnL0uEco2fCr2WvkXmt_9_Ox7wL_0CmzT8iuRp0aQ/edit?gid=1871111119#gid=1871111119"",""Details!A:X""),""SELECT Col8, Col9, Col10, Col11, Col12, Col13, Col14 WHERE Col2='""&B6&""'"",0)"),2.0) -> 2 | J6: =IFERROR(__xludf.DUMMYFUNCTION("""COMPUTED_VALUE"""),2.0) -> 2 | K6: =IFERROR(__xludf.DUMMYFUNCTION("""COMPUTED_VALUE"""),2.0) -> 2 | L6: =IFERROR(__xludf.DUMMYFUNCTION("""COMPUTED_VALUE"""),1.0) -> 1 | M6: =IFERROR(__xludf.DUMMYFUNCTION("""COMPUTED_VALUE"""),"Working") -> Working | N6: =IFERROR(__xludf.DUMMYFUNCTION("""COMPUTED_VALUE"""),"CORRECT") -> CORRECT | O6: =IFERROR(__xludf.DUMMYFUNCTION("""COMPUTED_VALUE"""),"LOAD PENDING") -> LOAD PENDING | P6: =IF(K6>I6,"Extra Theory Load Alloted","") | Q6: =IF(L6>J6,"Extra Lab Load Alloted","")
A7: 6 | B7: AD10931 | C7: Mr | D7: BALASAMY K | E7: =CONCATENATE(C7,".",D7) -> Mr.BALASAMY K | F7: Artificial Intelligence and Data Science | G7: Assistant Professor Level III | H7: balasamyk@bitsathy.ac.in | I7: =IFERROR(__xludf.DUMMYFUNCTION("QUERY(IMPORTRANGE(""https://docs.google.com/spreadsheets/d/1WWWnL0uEco2fCr2WvkXmt_9_Ox7wL_0CmzT8iuRp0aQ/edit?gid=1871111119#gid=1871111119"",""Details!A:X""),""SELECT Col8, Col9, Col10, Col11, Col12, Col13, Col14 WHERE Col2='""&B7&""'"",0)"),2.0) -> 2 | J7: =IFERROR(__xludf.DUMMYFUNCTION("""COMPUTED_VALUE"""),2.0) -> 2 | K7: =IFERROR(__xludf.DUMMYFUNCTION("""COMPUTED_VALUE"""),2.0) -> 2 | L7: =IFERROR(__xludf.DUMMYFUNCTION("""COMPUTED_VALUE"""),1.0) -> 1 | M7: =IFERROR(__xludf.DUMMYFUNCTION("""COMPUTED_VALUE"""),"Working") -> Working | N7: =IFERROR(__xludf.DUMMYFUNCTION("""COMPUTED_VALUE"""),"CORRECT") -> CORRECT | O7: =IFERROR(__xludf.DUMMYFUNCTION("""COMPUTED_VALUE"""),"LOAD PENDING") -> LOAD PENDING | P7: =IF(K7>I7,"Extra Theory Load Alloted","") | Q7: =IF(L7>J7,"Extra Lab Load Alloted","")
A8: 7 | B8: AD10936 | C8: Mr | D8: PRABANAND S C | E8: =CONCATENATE(C8,".",D8) -> Mr.PRABANAND S C | F8: Artificial Intelligence and Data Science | G8: Assistant Professor Level III | H8: prabanandsc@bitsathy.ac.in | I8: =IFERROR(__xludf.DUMMYFUNCTION("QUERY(IMPORTRANGE(""https://docs.google.com/spreadsheets/d/1WWWnL0uEco2fCr2WvkXmt_9_Ox7wL_0CmzT8iuRp0aQ/edit?gid=1871111119#gid=1871111119"",""Details!A:X""),""SELECT Col8, Col9, Col10, Col11, Col12, Col13, Col14 WHERE Col2='""&B8&""'"",0)"),2.0) -> 2 | J8: =IFERROR(__xludf.DUMMYFUNCTION("""COMPUTED_VALUE"""),2.0) -> 2 | K8: =IFERROR(__xludf.DUMMYFUNCTION("""COMPUTED_VALUE"""),0.0) -> 0 | L8: =IFERROR(__xludf.DUMMYFUNCTION("""COMPUTED_VALUE"""),0.0) -> 0 | M8: =IFERROR(__xludf.DUMMYFUNCTION("""COMPUTED_VALUE"""),"Working") -> Working | N8: =IFERROR(__xludf.DUMMYFUNCTION("""COMPUTED_VALUE"""),"LOAD PENDING") -> LOAD PENDING | O8: =IFERROR(__xludf.DUMMYFUNCTION("""COMPUTED_VALUE"""),"LOAD PENDING") -> LOAD PENDING | P8: =IF(K8>I8,"Extra Theory Load Alloted","") | Q8: =IF(L8>J8,"Extra Lab Load Alloted","")
A9: 8 | B9: AD10945 | C9: Mr | D9: SATHEESH N P | E9: =CONCATENATE(C9,".",D9) -> Mr.SATHEESH N P | F9: Artificial Intelligence and Data Science | G9: Assistant Professor Level I | H9: satheeshnp@bitsathy.ac.in | I9: =IFERROR(__xludf.DUMMYFUNCTION("QUERY(IMPORTRANGE(""https://docs.google.com/spreadsheets/d/1WWWnL0uEco2fCr2WvkXmt_9_Ox7wL_0CmzT8iuRp0aQ/edit?gid=1871111119#gid=1871111119"",""Details!A:X""),""SELECT Col8, Col9, Col10, Col11, Col12, Col13, Col14 WHERE Col2='""&B9&""'"",0)"),2.0) -> 2 | J9: =IFERROR(__xludf.DUMMYFUNCTION("""COMPUTED_VALUE"""),2.0) -> 2 | K9: =IFERROR(__xludf.DUMMYFUNCTION("""COMPUTED_VALUE"""),2.0) -> 2 | L9: =IFERROR(__xludf.DUMMYFUNCTION("""COMPUTED_VALUE"""),1.0) -> 1 | M9: =IFERROR(__xludf.DUMMYFUNCTION("""COMPUTED_VALUE"""),"Working") -> Working | N9: =IFERROR(__xludf.DUMMYFUNCTION("""COMPUTED_VALUE"""),"CORRECT") -> CORRECT | O9: =IFERROR(__xludf.DUMMYFUNCTION("""COMPUTED_VALUE"""),"LOAD PENDING") -> LOAD PENDING | P9: =IF(K9>I9,"Extra Theory Load Alloted","") | Q9: =IF(L9>J9,"Extra Lab Load Alloted","")
A10: 9 | B10: AD10953 | C10: Mr | D10: RAJ KUMAR V S | E10: =CONCATENATE(C10,".",D10) -> Mr.RAJ KUMAR V S | F10: Artificial Intelligence and Data Science | G10: Assistant Professor Level II | H10: rajkumarvs@bitsathy.ac.in | I10: =IFERROR(__xludf.DUMMYFUNCTION("QUERY(IMPORTRANGE(""https://docs.google.com/spreadsheets/d/1WWWnL0uEco2fCr2WvkXmt_9_Ox7wL_0CmzT8iuRp0aQ/edit?gid=1871111119#gid=1871111119"",""Details!A:X""),""SELECT Col8, Col9, Col10, Col11, Col12, Col13, Col14 WHERE Col2='""&B10&""'"",0)"),2.0) -> 2 | J10: =IFERROR(__xludf.DUMMYFUNCTION("""COMPUTED_VALUE"""),2.0) -> 2 | K10: =IFERROR(__xludf.DUMMYFUNCTION("""COMPUTED_VALUE"""),1.0) -> 1 | L10: =IFERROR(__xludf.DUMMYFUNCTION("""COMPUTED_VALUE"""),0.0) -> 0 | M10: =IFERROR(__xludf.DUMMYFUNCTION("""COMPUTED_VALUE"""),"Working") -> Working | N10: =IFERROR(__xludf.DUMMYFUNCTION("""COMPUTED_VALUE"""),"LOAD PENDING") -> LOAD PENDING | O10: =IFERROR(__xludf.DUMMYFUNCTION("""COMPUTED_VALUE"""),"LOAD PENDING") -> LOAD PENDING | P10: =IF(K10>I10,"Extra Theory Load Alloted","") | Q10: =IF(L10>J10,"Extra Lab Load Alloted","")
A11: 10 | B11: AD10955 | C11: Ms | D11: ESAKKI MADURA E | E11: =CONCATENATE(C11,".",D11) -> Ms.ESAKKI MADURA E | F11: Artificial Intelligence and Data Science | G11: Assistant Professor Level III | H11: esakkimadurae@bitsathy.ac.in | I11: =IFERROR(__xludf.DUMMYFUNCTION("QUERY(IMPORTRANGE(""https://docs.google.com/spreadsheets/d/1WWWnL0uEco2fCr2WvkXmt_9_Ox7wL_0CmzT8iuRp0aQ/edit?gid=1871111119#gid=1871111119"",""Details!A:X""),""SELECT Col8, Col9, Col10, Col11, Col12, Col13, Col14 WHERE Col2='""&B11&""'"",0)"),2.0) -> 2 | J11: =IFERROR(__xludf.DUMMYFUNCTION("""COMPUTED_VALUE"""),2.0) -> 2 | K11: =IFERROR(__xludf.DUMMYFUNCTION("""COMPUTED_VALUE"""),2.0) -> 2 | L11: =IFERROR(__xludf.DUMMYFUNCTION("""COMPUTED_VALUE"""),1.0) -> 1 | M11: =IFERROR(__xludf.DUMMYFUNCTION("""COMPUTED_VALUE"""),"Working") -> Working | N11: =IFERROR(__xludf.DUMMYFUNCTION("""COMPUTED_VALUE"""),"CORRECT") -> CORRECT | O11: =IFERROR(__xludf.DUMMYFUNCTION("""COMPUTED_VALUE"""),"LOAD PENDING") -> LOAD PENDING | P11: =IF(K11>I11,"Extra Theory Load Alloted","") | Q11: =IF(L11>J11,"Extra Lab Load Alloted","")
A12: 11 | B12: AD11009 | C12: Mrs | D12: DIVYABARATHI P | E12: =CONCATENATE(C12,".",D12) -> Mrs.DIVYABARATHI P | F12: Artificial Intelligence and Data Science | G12: Assistant Professor Level II | H12: divyabarathip@bitsathy.ac.in | I12: =IFERROR(__xludf.DUMMYFUNCTION("QUERY(IMPORTRANGE(""https://docs.google.com/spreadsheets/d/1WWWnL0uEco2fCr2WvkXmt_9_Ox7wL_0CmzT8iuRp0aQ/edit?gid=1871111119#gid=1871111119"",""Details!A:X""),""SELECT Col8, Col9, Col10, Col11, Col12, Col13, Col14 WHERE Col2='""&B12&""'"",0)"),2.0) -> 2 | J12: =IFERROR(__xludf.DUMMYFUNCTION("""COMPUTED_VALUE"""),2.0) -> 2 | K12: =IFERROR(__xludf.DUMMYFUNCTION("""COMPUTED_VALUE"""),2.0) -> 2 | L12: =IFERROR(__xludf.DUMMYFUNCTION("""COMPUTED_VALUE"""),1.0) -> 1 | M12: =IFERROR(__xludf.DUMMYFUNCTION("""COMPUTED_VALUE"""),"Working") -> Working | N12: =IFERROR(__xludf.DUMMYFUNCTION("""COMPUTED_VALUE"""),"CORRECT") -> CORRECT | O12: =IFERROR(__xludf.DUMMYFUNCTION("""COMPUTED_VALUE"""),"LOAD PENDING") -> LOAD PENDING | P12: =IF(K12>I12,"Extra Theory Load Alloted","") | Q12: =IF(L12>J12,"Extra Lab Load Alloted","")
A13: 12 | B13: AD11016 | C13: Mr | D13: SATHEESHKUMAR S | E13: =CONCATENATE(C13,".",D13) -> Mr.SATHEESHKUMAR S | F13: Artificial Intelligence and Data Science | G13: Assistant Professor Level II | H13: satheeshkumars@bitsathy.ac.in | I13: =IFERROR(__xludf.DUMMYFUNCTION("QUERY(IMPORTRANGE(""https://docs.google.com/spreadsheets/d/1WWWnL0uEco2fCr2WvkXmt_9_Ox7wL_0CmzT8iuRp0aQ/edit?gid=1871111119#gid=1871111119"",""Details!A:X""),""SELECT Col8, Col9, Col10, Col11, Col12, Col13, Col14 WHERE Col2='""&B13&""'"",0)"),2.0) -> 2 | J13: =IFERROR(__xludf.DUMMYFUNCTION("""COMPUTED_VALUE"""),2.0) -> 2 | K13: =IFERROR(__xludf.DUMMYFUNCTION("""COMPUTED_VALUE"""),2.0) -> 2 | L13: =IFERROR(__xludf.DUMMYFUNCTION("""COMPUTED_VALUE"""),1.0) -> 1 | M13: =IFERROR(__xludf.DUMMYFUNCTION("""COMPUTED_VALUE"""),"Working") -> Working | N13: =IFERROR(__xludf.DUMMYFUNCTION("""COMPUTED_VALUE"""),"CORRECT") -> CORRECT | O13: =IFERROR(__xludf.DUMMYFUNCTION("""COMPUTED_VALUE"""),"LOAD PENDING") -> LOAD PENDING | P13: =IF(K13>I13,"Extra Theory Load Alloted","") | Q13: =IF(L13>J13,"Extra Lab Load Alloted","")
A14: 13 | B14: AD11019 | C14: Mrs | D14: KIRUTHIGA R | E14: =CONCATENATE(C14,".",D14) -> Mrs.KIRUTHIGA R | F14: Artificial Intelligence and Data Science | G14: Assistant Professor Level I | H14: kiruthigar@bitsathy.ac.in | I14: =IFERROR(__xludf.DUMMYFUNCTION("QUERY(IMPORTRANGE(""https://docs.google.com/spreadsheets/d/1WWWnL0uEco2fCr2WvkXmt_9_Ox7wL_0CmzT8iuRp0aQ/edit?gid=1871111119#gid=1871111119"",""Details!A:X""),""SELECT Col8, Col9, Col10, Col11, Col12, Col13, Col14 WHERE Col2='""&B14&""'"",0)"),2.0) -> 2 | J14: =IFERROR(__xludf.DUMMYFUNCTION("""COMPUTED_VALUE"""),2.0) -> 2 | K14: =IFERROR(__xludf.DUMMYFUNCTION("""COMPUTED_VALUE"""),2.0) -> 2 | L14: =IFERROR(__xludf.DUMMYFUNCTION("""COMPUTED_VALUE"""),1.0) -> 1 | M14: =IFERROR(__xludf.DUMMYFUNCTION("""COMPUTED_VALUE"""),"Working") -> Working | N14: =IFERROR(__xludf.DUMMYFUNCTION("""COMPUTED_VALUE"""),"CORRECT") -> CORRECT | O14: =IFERROR(__xludf.DUMMYFUNCTION("""COMPUTED_VALUE"""),"LOAD PENDING") -> LOAD PENDING | P14: =IF(K14>I14,"Extra Theory Load Alloted","") | Q14: =IF(L14>J14,"Extra Lab Load Alloted","")
A15: 14 | B15: AD11023 | C15: Mrs | D15: VAANATHI S | E15: =CONCATENATE(C15,".",D15) -> Mrs.VAANATHI S | F15: Artificial Intelligence and Data Science | G15: Assistant Professor Level II | H15: vaanathi@bitsathy.ac.in | I15: =IFERROR(__xludf.DUMMYFUNCTION("QUERY(IMPORTRANGE(""https://docs.google.com/spreadsheets/d/1WWWnL0uEco2fCr2WvkXmt_9_Ox7wL_0CmzT8iuRp0aQ/edit?gid=1871111119#gid=1871111119"",""Details!A:X""),""SELECT Col8, Col9, Col10, Col11, Col12, Col13, Col14 WHERE Col2='""&B15&""'"",0)"),2.0) -> 2 | J15: =IFERROR(__xludf.DUMMYFUNCTION("""COMPUTED_VALUE"""),1.0) -> 1 | K15: =IFERROR(__xludf.DUMMYFUNCTION("""COMPUTED_VALUE"""),2.0) -> 2 | L15: =IFERROR(__xludf.DUMMYFUNCTION("""COMPUTED_VALUE"""),1.0) -> 1 | M15: =IFERROR(__xludf.DUMMYFUNCTION("""COMPUTED_VALUE"""),"Working") -> Working | N15: =IFERROR(__xludf.DUMMYFUNCTION("""COMPUTED_VALUE"""),"CORRECT") -> CORRECT | O15: =IFERROR(__xludf.DUMMYFUNCTION("""COMPUTED_VALUE"""),"CORRECT") -> CORRECT | P15: =IF(K15>I15,"Extra Theory Load Alloted","") | Q15: =IF(L15>J15,"Extra Lab Load Alloted","")
A16: 15 | B16: AD11026 | C16: Mr | D16: CHOZHARAJAN P | E16: =CONCATENATE(C16,".",D16) -> Mr.CHOZHARAJAN P | F16: Artificial Intelligence and Data Science | G16: Assistant Professor Level III | H16: chozharajanp@bitsathy.ac.in | I16: =IFERROR(__xludf.DUMMYFUNCTION("QUERY(IMPORTRANGE(""https://docs.google.com/spreadsheets/d/1WWWnL0uEco2fCr2WvkXmt_9_Ox7wL_0CmzT8iuRp0aQ/edit?gid=1871111119#gid=1871111119"",""Details!A:X""),""SELECT Col8, Col9, Col10, Col11, Col12, Col13, Col14 WHERE Col2='""&B16&""'"",0)"),2.0) -> 2 | J16: =IFERROR(__xludf.DUMMYFUNCTION("""COMPUTED_VALUE"""),2.0) -> 2 | K16: =IFERROR(__xludf.DUMMYFUNCTION("""COMPUTED_VALUE"""),2.0) -> 2 | L16: =IFERROR(__xludf.DUMMYFUNCTION("""COMPUTED_VALUE"""),1.0) -> 1 | M16: =IFERROR(__xludf.DUMMYFUNCTION("""COMPUTED_VALUE"""),"Working") -> Working | N16: =IFERROR(__xludf.DUMMYFUNCTION("""COMPUTED_VALUE"""),"CORRECT") -> CORRECT | O16: =IFERROR(__xludf.DUMMYFUNCTION("""COMPUTED_VALUE"""),"LOAD PENDING") -> LOAD PENDING | P16: =IF(K16>I16,"Extra Theory Load Alloted","") | Q16: =IF(L16>J16,"Extra Lab Load Alloted","")
A17: 16 | B17: AD11041 | C17: Mrs | D17: ASHFORN HERMINA J M | E17: =CONCATENATE(C17,".",D17) -> Mrs.ASHFORN HERMINA J M | F17: Artificial Intelligence and Data Science | G17: Assistant Professor Level I | H17: ashfornherminajm@bitsathy.ac.in | I17: =IFERROR(__xludf.DUMMYFUNCTION("QUERY(IMPORTRANGE(""https://docs.google.com/spreadsheets/d/1WWWnL0uEco2fCr2WvkXmt_9_Ox7wL_0CmzT8iuRp0aQ/edit?gid=1871111119#gid=1871111119"",""Details!A:X""),""SELECT Col8, Col9, Col10, Col11, Col12, Col13, Col14 WHERE Col2='""&B17&""'"",0)"),2.0) -> 2 | J17: =IFERROR(__xludf.DUMMYFUNCTION("""COMPUTED_VALUE"""),2.0) -> 2 | K17: =IFERROR(__xludf.DUMMYFUNCTION("""COMPUTED_VALUE"""),2.0) -> 2 | L17: =IFERROR(__xludf.DUMMYFUNCTION("""COMPUTED_VALUE"""),1.0) -> 1 | M17: =IFERROR(__xludf.DUMMYFUNCTION("""COMPUTED_VALUE"""),"Working") -> Working | N17: =IFERROR(__xludf.DUMMYFUNCTION("""COMPUTED_VALUE"""),"CORRECT") -> CORRECT | O17: =IFERROR(__xludf.DUMMYFUNCTION("""COMPUTED_VALUE"""),"LOAD PENDING") -> LOAD PENDING | P17: =IF(K17>I17,"Extra Theory Load Alloted","") | Q17: =IF(L17>J17,"Extra Lab Load Alloted","")
A18: 17 | B18: AD11042 | C18: Mrs | D18: JEEVITHA S V | E18: =CONCATENATE(C18,".",D18) -> Mrs.JEEVITHA S V | F18: Artificial Intelligence and Data Science | G18: Assistant Professor Level I | H18: jeevithasv@bitsathy.ac.in | I18: =IFERROR(__xludf.DUMMYFUNCTION("QUERY(IMPORTRANGE(""https://docs.google.com/spreadsheets/d/1WWWnL0uEco2fCr2WvkXmt_9_Ox7wL_0CmzT8iuRp0aQ/edit?gid=1871111119#gid=1871111119"",""Details!A:X""),""SELECT Col8, Col9, Col10, Col11, Col12, Col13, Col14 WHERE Col2='""&B18&""'"",0)"),2.0) -> 2 | J18: =IFERROR(__xludf.DUMMYFUNCTION("""COMPUTED_VALUE"""),2.0) -> 2 | K18: =IFERROR(__xludf.DUMMYFUNCTION("""COMPUTED_VALUE"""),2.0) -> 2 | L18: =IFERROR(__xludf.DUMMYFUNCTION("""COMPUTED_VALUE"""),1.0) -> 1 | M18: =IFERROR(__xludf.DUMMYFUNCTION("""COMPUTED_VALUE"""),"Working") -> Working | N18: =IFERROR(__xludf.DUMMYFUNCTION("""COMPUTED_VALUE"""),"CORRECT") -> CORRECT | O18: =IFERROR(__xludf.DUMMYFUNCTION("""COMPUTED_VALUE"""),"LOAD PENDING") -> LOAD PENDING | P18: =IF(K18>I18,"Extra Theory Load Alloted","") | Q18: =IF(L18>J18,"Extra Lab Load Alloted","")
A19: 18 | B19: AD11068 | C19: Ms | D19: BENITA GRACIA THANGAM J | E19: =CONCATENATE(C19,".",D19) -> Ms.BENITA GRACIA THANGAM J | F19: Artificial Intelligence and Data Science | G19: Assistant Professor Level I | H19: benitagraciathangam@bitsathy.ac.in | I19: =IFERROR(__xludf.DUMMYFUNCTION("QUERY(IMPORTRANGE(""https://docs.google.com/spreadsheets/d/1WWWnL0uEco2fCr2WvkXmt_9_Ox7wL_0CmzT8iuRp0aQ/edit?gid=1871111119#gid=1871111119"",""Details!A:X""),""SELECT Col8, Col9, Col10, Col11, Col12, Col13, Col14 WHERE Col2='""&B19&""'"",0)"),2.0) -> 2 | J19: =IFERROR(__xludf.DUMMYFUNCTION("""COMPUTED_VALUE"""),2.0) -> 2 | K19: =IFERROR(__xludf.DUMMYFUNCTION("""COMPUTED_VALUE"""),2.0) -> 2 | L19: =IFERROR(__xludf.DUMMYFUNCTION("""COMPUTED_VALUE"""),1.0) -> 1 | M19: =IFERROR(__xludf.DUMMYFUNCTION("""COMPUTED_VALUE"""),"Working") -> Working | N19: =IFERROR(__xludf.DUMMYFUNCTION("""COMPUTED_VALUE"""),"CORRECT") -> CORRECT | O19: =IFERROR(__xludf.DUMMYFUNCTION("""COMPUTED_VALUE"""),"LOAD PENDING") -> LOAD PENDING | P19: =IF(K19>I19,"Extra Theory Load Alloted","") | Q19: =IF(L19>J19,"Extra Lab Load Alloted","")
A20: 19 | B20: AD11069 | C20: Mr | D20: PREMKUMAR C | E20: =CONCATENATE(C20,".",D20) -> Mr.PREMKUMAR C | F20: Artificial Intelligence and Data Science | G20: Assistant Professor Level I | H20: premkumar@bitsathy.ac.in | I20: =IFERROR(__xludf.DUMMYFUNCTION("QUERY(IMPORTRANGE(""https://docs.google.com/spreadsheets/d/1WWWnL0uEco2fCr2WvkXmt_9_Ox7wL_0CmzT8iuRp0aQ/edit?gid=1871111119#gid=1871111119"",""Details!A:X""),""SELECT Col8, Col9, Col10, Col11, Col12, Col13, Col14 WHERE Col2='""&B20&""'"",0)"),2.0) -> 2 | J20: =IFERROR(__xludf.DUMMYFUNCTION("""COMPUTED_VALUE"""),2.0) -> 2 | K20: =IFERROR(__xludf.DUMMYFUNCTION("""COMPUTED_VALUE"""),2.0) -> 2 | L20: =IFERROR(__xludf.DUMMYFUNCTION("""COMPUTED_VALUE"""),1.0) -> 1 | M20: =IFERROR(__xludf.DUMMYFUNCTION("""COMPUTED_VALUE"""),"Working") -> Working | N20: =IFERROR(__xludf.DUMMYFUNCTION("""COMPUTED_VALUE"""),"CORRECT") -> CORRECT | O20: =IFERROR(__xludf.DUMMYFUNCTION("""COMPUTED_VALUE"""),"LOAD PENDING") -> LOAD PENDING | P20: =IF(K20>I20,"Extra Theory Load Alloted","") | Q20: =IF(L20>J20,"Extra Lab Load Alloted","")
A21: 20 | B21: AD1108 | C21: Dr | D21: SUNDARA MURTHY S | E21: =CONCATENATE(C21,".",D21) -> Dr.SUNDARA MURTHY S | F21: Artificial Intelligence and Data Science | G21: Professor | H21: sundaramurthys@bitsathy.ac.in | I21: =IFERROR(__xludf.DUMMYFUNCTION("QUERY(IMPORTRANGE(""https://docs.google.com/spreadsheets/d/1WWWnL0uEco2fCr2WvkXmt_9_Ox7wL_0CmzT8iuRp0aQ/edit?gid=1871111119#gid=1871111119"",""Details!A:X""),""SELECT Col8, Col9, Col10, Col11, Col12, Col13, Col14 WHERE Col2='""&B21&""'"",0)"),1.0) -> 1 | J21: =IFERROR(__xludf.DUMMYFUNCTION("""COMPUTED_VALUE"""),0.0) -> 0 | K21: =IFERROR(__xludf.DUMMYFUNCTION("""COMPUTED_VALUE"""),1.0) -> 1 | L21: =IFERROR(__xludf.DUMMYFUNCTION("""COMPUTED_VALUE"""),0.0) -> 0 | M21: =IFERROR(__xludf.DUMMYFUNCTION("""COMPUTED_VALUE"""),"Working") -> Working | N21: =IFERROR(__xludf.DUMMYFUNCTION("""COMPUTED_VALUE"""),"CORRECT") -> CORRECT | O21: =IFERROR(__xludf.DUMMYFUNCTION("""COMPUTED_VALUE"""),"CORRECT") -> CORRECT | P21: =IF(K21>I21,"Extra Theory Load Alloted","") | Q21: =IF(L21>J21,"Extra Lab Load Alloted","")
A22: 21 | B22: AD11089 | C22: Mrs | D22: RESHMI T S | E22: =CONCATENATE(C22,".",D22) -> Mrs.RESHMI T S | F22: Artificial Intelligence and Data Science | G22: Assistant Professor Level I | H22: reshmits@bitsathy.ac.in | I22: =IFERROR(__xludf.DUMMYFUNCTION("QUERY(IMPORTRANGE(""https://docs.google.com/spreadsheets/d/1WWWnL0uEco2fCr2WvkXmt_9_Ox7wL_0CmzT8iuRp0aQ/edit?gid=1871111119#gid=1871111119"",""Details!A:X""),""SELECT Col8, Col9, Col10, Col11, Col12, Col13, Col14 WHERE Col2='""&B22&""'"",0)"),2.0) -> 2 | J22: =IFERROR(__xludf.DUMMYFUNCTION("""COMPUTED_VALUE"""),2.0) -> 2 | K22: =IFERROR(__xludf.DUMMYFUNCTION("""COMPUTED_VALUE"""),2.0) -> 2 | L22: =IFERROR(__xludf.DUMMYFUNCTION("""COMPUTED_VALUE"""),1.0) -> 1 | M22: =IFERROR(__xludf.DUMMYFUNCTION("""COMPUTED_VALUE"""),"Working") -> Working | N22: =IFERROR(__xludf.DUMMYFUNCTION("""COMPUTED_VALUE"""),"CORRECT") -> CORRECT | O22: =IFERROR(__xludf.DUMMYFUNCTION("""COMPUTED_VALUE"""),"LOAD PENDING") -> LOAD PENDING | P22: =IF(K22>I22,"Extra Theory Load Alloted","") | Q22: =IF(L22>J22,"Extra Lab Load Alloted","")
A23: 22 | B23: AD11096 | C23: Dr | D23: SUBBULAKSHMI M | E23: =CONCATENATE(C23,".",D23) -> Dr.SUBBULAKSHMI M | F23: Artificial Intelligence and Data Science | G23: Assistant Professor Level III | H23: subbulakshmi@bitsathy.ac.in | I23: =IFERROR(__xludf.DUMMYFUNCTION("QUERY(IMPORTRANGE(""https://docs.google.com/spreadsheets/d/1WWWnL0uEco2fCr2WvkXmt_9_Ox7wL_0CmzT8iuRp0aQ/edit?gid=1871111119#gid=1871111119"",""Details!A:X""),""SELECT Col8, Col9, Col10, Col11, Col12, Col13, Col14 WHERE Col2='""&B23&""'"",0)"),2.0) -> 2 | J23: =IFERROR(__xludf.DUMMYFUNCTION("""COMPUTED_VALUE"""),2.0) -> 2 | K23: =IFERROR(__xludf.DUMMYFUNCTION("""COMPUTED_VALUE"""),2.0) -> 2 | L23: =IFERROR(__xludf.DUMMYFUNCTION("""COMPUTED_VALUE"""),1.0) -> 1 | M23: =IFERROR(__xludf.DUMMYFUNCTION("""COMPUTED_VALUE"""),"Working") -> Working | N23: =IFERROR(__xludf.DUMMYFUNCTION("""COMPUTED_VALUE"""),"CORRECT") -> CORRECT | O23: =IFERROR(__xludf.DUMMYFUNCTION("""COMPUTED_VALUE"""),"LOAD PENDING") -> LOAD PENDING | P23: =IF(K23>I23,"Extra Theory Load Alloted","") | Q23: =IF(L23>J23,"Extra Lab Load Alloted","")
A24: 23 | B24: AD11104 | C24: Mrs | D24: KALPANA R | E24: =CONCATENATE(C24,".",D24) -> Mrs.KALPANA R | F24: Artificial Intelligence and Data Science | G24: Assistant Professor Level I | H24: kalpana@bitsathy.ac.in | I24: =IFERROR(__xludf.DUMMYFUNCTION("QUERY(IMPORTRANGE(""https://docs.google.com/spreadsheets/d/1WWWnL0uEco2fCr2WvkXmt_9_Ox7wL_0CmzT8iuRp0aQ/edit?gid=1871111119#gid=1871111119"",""Details!A:X""),""SELECT Col8, Col9, Col10, Col11, Col12, Col13, Col14 WHERE Col2='""&B24&""'"",0)"),2.0) -> 2 | J24: =IFERROR(__xludf.DUMMYFUNCTION("""COMPUTED_VALUE"""),2.0) -> 2 | K24: =IFERROR(__xludf.DUMMYFUNCTION("""COMPUTED_VALUE"""),2.0) -> 2 | L24: =IFERROR(__xludf.DUMMYFUNCTION("""COMPUTED_VALUE"""),1.0) -> 1 | M24: =IFERROR(__xludf.DUMMYFUNCTION("""COMPUTED_VALUE"""),"Working") -> Working | N24: =IFERROR(__xludf.DUMMYFUNCTION("""COMPUTED_VALUE"""),"CORRECT") -> CORRECT | O24: =IFERROR(__xludf.DUMMYFUNCTION("""COMPUTED_VALUE"""),"LOAD PENDING") -> LOAD PENDING | P24: =IF(K24>I24,"Extra Theory Load Alloted","") | Q24: =IF(L24>J24,"Extra Lab Load Alloted","")
A25: 24 | B25: AD11111 | C25: Ms | D25: SURIYA V | E25: =CONCATENATE(C25,".",D25) -> Ms.SURIYA V | F25: Artificial Intelligence and Data Science | G25: Assistant Professor Level I | H25: suriya@bitsathy.ac.in | I25: =IFERROR(__xludf.DUMMYFUNCTION("QUERY(IMPORTRANGE(""https://docs.google.com/spreadsheets/d/1WWWnL0uEco2fCr2WvkXmt_9_Ox7wL_0CmzT8iuRp0aQ/edit?gid=1871111119#gid=1871111119"",""Details!A:X""),""SELECT Col8, Col9, Col10, Col11, Col12, Col13, Col14 WHERE Col2='""&B25&""'"",0)"),2.0) -> 2 | J25: =IFERROR(__xludf.DUMMYFUNCTION("""COMPUTED_VALUE"""),2.0) -> 2 | K25: =IFERROR(__xludf.DUMMYFUNCTION("""COMPUTED_VALUE"""),2.0) -> 2 | L25: =IFERROR(__xludf.DUMMYFUNCTION("""COMPUTED_VALUE"""),1.0) -> 1 | M25: =IFERROR(__xludf.DUMMYFUNCTION("""COMPUTED_VALUE"""),"Working") -> Working | N25: =IFERROR(__xludf.DUMMYFUNCTION("""COMPUTED_VALUE"""),"CORRECT") -> CORRECT | O25: =IFERROR(__xludf.DUMMYFUNCTION("""COMPUTED_VALUE"""),"LOAD PENDING") -> LOAD PENDING | P25: =IF(K25>I25,"Extra Theory Load Alloted","") | Q25: =IF(L25>J25,"Extra Lab Load Alloted","")
A26: 25 | B26: AD11112 | C26: Mrs | D26: HEMA PRIYA D | E26: =CONCATENATE(C26,".",D26) -> Mrs.HEMA PRIYA D | F26: Artificial Intelligence and Data Science | G26: Assistant Professor Level I | H26: hemapriyad@bitsathy.ac.in | I26: =IFERROR(__xludf.DUMMYFUNCTION("QUERY(IMPORTRANGE(""https://docs.google.com/spreadsheets/d/1WWWnL0uEco2fCr2WvkXmt_9_Ox7wL_0CmzT8iuRp0aQ/edit?gid=1871111119#gid=1871111119"",""Details!A:X""),""SELECT Col8, Col9, Col10, Col11, Col12, Col13, Col14 WHERE Col2='""&B26&""'"",0)"),2.0) -> 2 | J26: =IFERROR(__xludf.DUMMYFUNCTION("""COMPUTED_VALUE"""),2.0) -> 2 | K26: =IFERROR(__xludf.DUMMYFUNCTION("""COMPUTED_VALUE"""),1.0) -> 1 | L26: =IFERROR(__xludf.DUMMYFUNCTION("""COMPUTED_VALUE"""),1.0) -> 1 | M26: =IFERROR(__xludf.DUMMYFUNCTION("""COMPUTED_VALUE"""),"Working") -> Working | N26: =IFERROR(__xludf.DUMMYFUNCTION("""COMPUTED_VALUE"""),"LOAD PENDING") -> LOAD PENDING | O26: =IFERROR(__xludf.DUMMYFUNCTION("""COMPUTED_VALUE"""),"LOAD PENDING") -> LOAD PENDING | P26: =IF(K26>I26,"Extra Theory Load Alloted","") | Q26: =IF(L26>J26,"Extra Lab Load Alloted","")
A27: 26 | B27: AD11114 | C27: Mrs | D27: MANJU M | E27: =CONCATENATE(C27,".",D27) -> Mrs.MANJU M | F27: Artificial Intelligence and Data Science | G27: Assistant Professor Level I | H27: manju@bitsathy.ac.in | I27: =IFERROR(__xludf.DUMMYFUNCTION("QUERY(IMPORTRANGE(""https://docs.google.com/spreadsheets/d/1WWWnL0uEco2fCr2WvkXmt_9_Ox7wL_0CmzT8iuRp0aQ/edit?gid=1871111119#gid=1871111119"",""Details!A:X""),""SELECT Col8, Col9, Col10, Col11, Col12, Col13, Col14 WHERE Col2='""&B27&""'"",0)"),2.0) -> 2 | J27: =IFERROR(__xludf.DUMMYFUNCTION("""COMPUTED_VALUE"""),2.0) -> 2 | K27: =IFERROR(__xludf.DUMMYFUNCTION("""COMPUTED_VALUE"""),2.0) -> 2 | L27: =IFERROR(__xludf.DUMMYFUNCTION("""COMPUTED_VALUE"""),1.0) -> 1 | M27: =IFERROR(__xludf.DUMMYFUNCTION("""COMPUTED_VALUE"""),"Working") -> Working | N27: =IFERROR(__xludf.DUMMYFUNCTION("""COMPUTED_VALUE"""),"CORRECT") -> CORRECT | O27: =IFERROR(__xludf.DUMMYFUNCTION("""COMPUTED_VALUE"""),"LOAD PENDING") -> LOAD PENDING | P27: =IF(K27>I27,"Extra Theory Load Alloted","") | Q27: =IF(L27>J27,"Extra Lab Load Alloted","")
A28: 27 | B28: AD11116 | C28: Ms | D28: PRIYADHARSHNI S | E28: =CONCATENATE(C28,".",D28) -> Ms.PRIYADHARSHNI S | F28: Artificial Intelligence and Data Science | G28: Assistant Professor Level I | H28: priyadharshni@bitsathy.ac.in | I28: =IFERROR(__xludf.DUMMYFUNCTION("QUERY(IMPORTRANGE(""https://docs.google.com/spreadsheets/d/1WWWnL0uEco2fCr2WvkXmt_9_Ox7wL_0CmzT8iuRp0aQ/edit?gid=1871111119#gid=1871111119"",""Details!A:X""),""SELECT Col8, Col9, Col10, Col11, Col12, Col13, Col14 WHERE Col2='""&B28&""'"",0)"),2.0) -> 2 | J28: =IFERROR(__xludf.DUMMYFUNCTION("""COMPUTED_VALUE"""),2.0) -> 2 | K28: =IFERROR(__xludf.DUMMYFUNCTION("""COMPUTED_VALUE"""),2.0) -> 2 | L28: =IFERROR(__xludf.DUMMYFUNCTION("""COMPUTED_VALUE"""),1.0) -> 1 | M28: =IFERROR(__xludf.DUMMYFUNCTION("""COMPUTED_VALUE"""),"Working") -> Working | N28: =IFERROR(__xludf.DUMMYFUNCTION("""COMPUTED_VALUE"""),"CORRECT") -> CORRECT | O28: =IFERROR(__xludf.DUMMYFUNCTION("""COMPUTED_VALUE"""),"LOAD PENDING") -> LOAD PENDING | P28: =IF(K28>I28,"Extra Theory Load Alloted","") | Q28: =IF(L28>J28,"Extra Lab Load Alloted","")
A29: 28 | B29: AD11164 | C29: Mr | D29: SASSON TAFFWIN MOSES S | E29: =CONCATENATE(C29,".",D29) -> Mr.SASSON TAFFWIN MOSES S | F29: Artificial Intelligence and Data Science | G29: Assistant Professor Level I | H29: sassontaffwinmosess@bitsathy.ac.in | I29: =IFERROR(__xludf.DUMMYFUNCTION("QUERY(IMPORTRANGE(""https://docs.google.com/spreadsheets/d/1WWWnL0uEco2fCr2WvkXmt_9_Ox7wL_0CmzT8iuRp0aQ/edit?gid=1871111119#gid=1871111119"",""Details!A:X""),""SELECT Col8, Col9, Col10, Col11, Col12, Col13, Col14 WHERE Col2='""&B29&""'"",0)"),2.0) -> 2 | J29: =IFERROR(__xludf.DUMMYFUNCTION("""COMPUTED_VALUE"""),2.0) -> 2 | K29: =IFERROR(__xludf.DUMMYFUNCTION("""COMPUTED_VALUE"""),2.0) -> 2 | L29: =IFERROR(__xludf.DUMMYFUNCTION("""COMPUTED_VALUE"""),1.0) -> 1 | M29: =IFERROR(__xludf.DUMMYFUNCTION("""COMPUTED_VALUE"""),"Working") -> Working | N29: =IFERROR(__xludf.DUMMYFUNCTION("""COMPUTED_VALUE"""),"CORRECT") -> CORRECT | O29: =IFERROR(__xludf.DUMMYFUNCTION("""COMPUTED_VALUE"""),"LOAD PENDING") -> LOAD PENDING | P29: =IF(K29>I29,"Extra Theory Load Alloted","") | Q29: =IF(L29>J29,"Extra Lab Load Alloted","")
A30: 29 | B30: AD11169 | C30: Mrs | D30: MANOCHITRA A S | E30: =CONCATENATE(C30,".",D30) -> Mrs.MANOCHITRA A S | F30: Artificial Intelligence and Data Science | G30: Assistant Professor Level I | H30: manochitra@bitsathy.ac.in | I30: =IFERROR(__xludf.DUMMYFUNCTION("QUERY(IMPORTRANGE(""https://docs.google.com/spreadsheets/d/1WWWnL0uEco2fCr2WvkXmt_9_Ox7wL_0CmzT8iuRp0aQ/edit?gid=1871111119#gid=1871111119"",""Details!A:X""),""SELECT Col8, Col9, Col10, Col11, Col12, Col13, Col14 WHERE Col2='""&B30&""'"",0)"),2.0) -> 2 | J30: =IFERROR(__xludf.DUMMYFUNCTION("""COMPUTED_VALUE"""),2.0) -> 2 | K30: =IFERROR(__xludf.DUMMYFUNCTION("""COMPUTED_VALUE"""),2.0) -> 2 | L30: =IFERROR(__xludf.DUMMYFUNCTION("""COMPUTED_VALUE"""),1.0) -> 1 | M30: =IFERROR(__xludf.DUMMYFUNCTION("""COMPUTED_VALUE"""),"Working") -> Working | N30: =IFERROR(__xludf.DUMMYFUNCTION("""COMPUTED_VALUE"""),"CORRECT") -> CORRECT | O30: =IFERROR(__xludf.DUMMYFUNCTION("""COMPUTED_VALUE"""),"LOAD PENDING") -> LOAD PENDING | P30: =IF(K30>I30,"Extra Theory Load Alloted","") | Q30: =IF(L30>J30,"Extra Lab Load Alloted","")
A31: 30 | B31: AD11193 | C31: Mr | D31: NAVANEETH KUMAR K | E31: =CONCATENATE(C31,".",D31) -> Mr.NAVANEETH KUMAR K | F31: Artificial Intelligence and Data Science | G31: Assistant Professor Level III | H31: navaneethkumark@bitsathy.ac.in | I31: =IFERROR(__xludf.DUMMYFUNCTION("QUERY(IMPORTRANGE(""https://docs.google.com/spreadsheets/d/1WWWnL0uEco2fCr2WvkXmt_9_Ox7wL_0CmzT8iuRp0aQ/edit?gid=1871111119#gid=1871111119"",""Details!A:X""),""SELECT Col8, Col9, Col10, Col11, Col12, Col13, Col14 WHERE Col2='""&B31&""'"",0)"),"") | K31: =IFERROR(__xludf.DUMMYFUNCTION("""COMPUTED_VALUE"""),1.0) -> 1 | L31: =IFERROR(__xludf.DUMMYFUNCTION("""COMPUTED_VALUE"""),0.0) -> 0 | M31: =IFERROR(__xludf.DUMMYFUNCTION("""COMPUTED_VALUE"""),"Working") -> Working | N31: =IFERROR(__xludf.DUMMYFUNCTION("""COMPUTED_VALUE"""),"#N/A") -> #N/A | O31: =IFERROR(__xludf.DUMMYFUNCTION("""COMPUTED_VALUE"""),"CORRECT") -> CORRECT | P31: =IF(K31>I31,"Extra Theory Load Alloted","") -> Extra Theory Load Alloted | Q31: =IF(L31>J31,"Extra Lab Load Alloted","")
A32: 31 | B32: AD1444 | C32: Dr | D32: GOMATHI R | E32: =CONCATENATE(C32,".",D32) -> Dr.GOMATHI R | F32: Artificial Intelligence and Data Science | G32: Professor | H32: gomathir@bitsathy.ac.in | I32: =IFERROR(__xludf.DUMMYFUNCTION("QUERY(IMPORTRANGE(""https://docs.google.com/spreadsheets/d/1WWWnL0uEco2fCr2WvkXmt_9_Ox7wL_0CmzT8iuRp0aQ/edit?gid=1871111119#gid=1871111119"",""Details!A:X""),""SELECT Col8, Col9, Col10, Col11, Col12, Col13, Col14 WHERE Col2='""&B32&""'"",0)"),1.0) -> 1 | J32: =IFERROR(__xludf.DUMMYFUNCTION("""COMPUTED_VALUE"""),0.0) -> 0 | K32: =IFERROR(__xludf.DUMMYFUNCTION("""COMPUTED_VALUE"""),1.0) -> 1 | L32: =IFERROR(__xludf.DUMMYFUNCTION("""COMPUTED_VALUE"""),0.0) -> 0 | M32: =IFERROR(__xludf.DUMMYFUNCTION("""COMPUTED_VALUE"""),"Working") -> Working | N32: =IFERROR(__xludf.DUMMYFUNCTION("""COMPUTED_VALUE"""),"CORRECT") -> CORRECT | O32: =IFERROR(__xludf.DUMMYFUNCTION("""COMPUTED_VALUE"""),"CORRECT") -> CORRECT | P32: =IF(K32>I32,"Extra Theory Load Alloted","") | Q32: =IF(L32>J32,"Extra Lab Load Alloted","")
A33: 32 | B33: AD1963 | C33: Dr | D33: NANDHINI S S | E33: =CONCATENATE(C33,".",D33) -> Dr.NANDHINI S S | F33: Artificial Intelligence and Data Science | G33: Associate Professor | H33: nandhiniss@bitsathy.ac.in | I33: =IFERROR(__xludf.DUMMYFUNCTION("QUERY(IMPORTRANGE(""https://docs.google.com/spreadsheets/d/1WWWnL0uEco2fCr2WvkXmt_9_Ox7wL_0CmzT8iuRp0aQ/edit?gid=1871111119#gid=1871111119"",""Details!A:X""),""SELECT Col8, Col9, Col10, Col11, Col12, Col13, Col14 WHERE Col2='""&B33&""'"",0)"),0.0) -> 0 | J33: =IFERROR(__xludf.DUMMYFUNCTION("""COMPUTED_VALUE"""),0.0) -> 0 | K33: =IFERROR(__xludf.DUMMYFUNCTION("""COMPUTED_VALUE"""),0.0) -> 0 | L33: =IFERROR(__xludf.DUMMYFUNCTION("""COMPUTED_VALUE"""),0.0) -> 0 | M33: =IFERROR(__xludf.DUMMYFUNCTION("""COMPUTED_VALUE"""),"Working") -> Working | N33: =IFERROR(__xludf.DUMMYFUNCTION("""COMPUTED_VALUE"""),"CORRECT") -> CORRECT | O33: =IFERROR(__xludf.DUMMYFUNCTION("""COMPUTED_VALUE"""),"CORRECT") -> CORRECT | P33: =IF(K33>I33,"Extra Theory Load Alloted","") | Q33: =IF(L33>J33,"Extra Lab Load Alloted","")
A34: 33 | B34: AG10092 | C34: Dr | D34: VASUDEVAN M | E34: =CONCATENATE(C34,".",D34) -> Dr.VASUDEVAN M | F34: Agricultural Engineering | G34: Associate Professor | H34: vasudevan@bitsathy.ac.in | I34: =IFERROR(__xludf.DUMMYFUNCTION("QUERY(IMPORTRANGE(""https://docs.google.com/spreadsheets/d/1WWWnL0uEco2fCr2WvkXmt_9_Ox7wL_0CmzT8iuRp0aQ/edit?gid=1871111119#gid=1871111119"",""Details!A:X""),""SELECT Col8, Col9, Col10, Col11, Col12, Col13, Col14 WHERE Col2='""&B34&""'"",0)"),2.0) -> 2 | J34: =IFERROR(__xludf.DUMMYFUNCTION("""COMPUTED_VALUE"""),1.0) -> 1 | K34: =IFERROR(__xludf.DUMMYFUNCTION("""COMPUTED_VALUE"""),2.0) -> 2 | L34: =IFERROR(__xludf.DUMMYFUNCTION("""COMPUTED_VALUE"""),1.0) -> 1 | M34: =IFERROR(__xludf.DUMMYFUNCTION("""COMPUTED_VALUE"""),"Working") -> Working | N34: =IFERROR(__xludf.DUMMYFUNCTION("""COMPUTED_VALUE"""),"CORRECT") -> CORRECT | O34: =IFERROR(__xludf.DUMMYFUNCTION("""COMPUTED_VALUE"""),"CORRECT") -> CORRECT | P34: =IF(K34>I34,"Extra Theory Load Alloted","") | Q34: =IF(L34>J34,"Extra Lab Load Alloted","")
A35: 34 | B35: AG10172 | C35: Dr | D35: VINOTH KUMAR J | E35: =CONCATENATE(C35,".",D35) -> Dr.VINOTH KUMAR J | F35: Agricultural Engineering | G35: Assistant Professor Level III | H35: vinothkumar@bitsathy.ac.in | I35: =IFERROR(__xludf.DUMMYFUNCTION("QUERY(IMPORTRANGE(""https://docs.google.com/spreadsheets/d/1WWWnL0uEco2fCr2WvkXmt_9_Ox7wL_0CmzT8iuRp0aQ/edit?gid=1871111119#gid=1871111119"",""Details!A:X""),""SELECT Col8, Col9, Col10, Col11, Col12, Col13, Col14 WHERE Col2='""&B35&""'"",0)"),1.0) -> 1 | J35: =IFERROR(__xludf.DUMMYFUNCTION("""COMPUTED_VALUE"""),0.0) -> 0 | K35: =IFERROR(__xludf.DUMMYFUNCTION("""COMPUTED_VALUE"""),1.0) -> 1 | L35: =IFERROR(__xludf.DUMMYFUNCTION("""COMPUTED_VALUE"""),1.0) -> 1 | M35: =IFERROR(__xludf.DUMMYFUNCTION("""COMPUTED_VALUE"""),"Working") -> Working | N35: =IFERROR(__xludf.DUMMYFUNCTION("""COMPUTED_VALUE"""),"CORRECT") -> CORRECT | O35: =IFERROR(__xludf.DUMMYFUNCTION("""COMPUTED_VALUE"""),"CORRECT") -> CORRECT | P35: =IF(K35>I35,"Extra Theory Load Alloted","") | Q35: =IF(L35>J35,"Extra Lab Load Alloted","") -> Extra Lab Load Alloted
A36: 35 | B36: AG10503 | C36: Dr | D36: CHELLADURAI V | E36: =CONCATENATE(C36,".",D36) -> Dr.CHELLADURAI V | F36: Agricultural Engineering | G36: Associate Professor | H36: chelladurai@bitsathy.ac.in | I36: =IFERROR(__xludf.DUMMYFUNCTION("QUERY(IMPORTRANGE(""https://docs.google.com/spreadsheets/d/1WWWnL0uEco2fCr2WvkXmt_9_Ox7wL_0CmzT8iuRp0aQ/edit?gid=1871111119#gid=1871111119"",""Details!A:X""),""SELECT Col8, Col9, Col10, Col11, Col12, Col13, Col14 WHERE Col2='""&B36&""'"",0)"),1.0) -> 1 | J36: =IFERROR(__xludf.DUMMYFUNCTION("""COMPUTED_VALUE"""),0.0) -> 0 | K36: =IFERROR(__xludf.DUMMYFUNCTION("""COMPUTED_VALUE"""),1.0) -> 1 | L36: =IFERROR(__xludf.DUMMYFUNCTION("""COMPUTED_VALUE"""),0.0) -> 0 | M36: =IFERROR(__xludf.DUMMYFUNCTION("""COMPUTED_VALUE"""),"Working") -> Working | N36: =IFERROR(__xludf.DUMMYFUNCTION("""COMPUTED_VALUE"""),"CORRECT") -> CORRECT | O36: =IFERROR(__xludf.DUMMYFUNCTION("""COMPUTED_VALUE"""),"CORRECT") -> CORRECT | P36: =IF(K36>I36,"Extra Theory Load Alloted","") | Q36: =IF(L36>J36,"Extra Lab Load Alloted","")
A37: 36 | B37: AG10895 | C37: Ms | D37: ANANTHI D | E37: =CONCATENATE(C37,".",D37) -> Ms.ANANTHI D | F37: Agricultural Engineering | G37: Assistant Professor Level I | H37: ananthid@bitsathy.ac.in | I37: =IFERROR(__xludf.DUMMYFUNCTION("QUERY(IMPORTRANGE(""https://docs.google.com/spreadsheets/d/1WWWnL0uEco2fCr2WvkXmt_9_Ox7wL_0CmzT8iuRp0aQ/edit?gid=1871111119#gid=1871111119"",""Details!A:X""),""SELECT Col8, Col9, Col10, Col11, Col12, Col13, Col14 WHERE Col2='""&B37&""'"",0)"),2.0) -> 2 | J37: =IFERROR(__xludf.DUMMYFUNCTION("""COMPUTED_VALUE"""),2.0) -> 2 | K37: =IFERROR(__xludf.DUMMYFUNCTION("""COMPUTED_VALUE"""),2.0) -> 2 | L37: =IFERROR(__xludf.DUMMYFUNCTION("""COMPUTED_VALUE"""),1.0) -> 1 | M37: =IFERROR(__xludf.DUMMYFUNCTION("""COMPUTED_VALUE"""),"Working") -> Working | N37: =IFERROR(__xludf.DUMMYFUNCTION("""COMPUTED_VALUE"""),"CORRECT") -> CORRECT | O37: =IFERROR(__xludf.DUMMYFUNCTION("""COMPUTED_VALUE"""),"LOAD PENDING") -> LOAD PENDING | P37: =IF(K37>I37,"Extra Theory Load Alloted","") | Q37: =IF(L37>J37,"Extra Lab Load Alloted","")
A38: 37 | B38: AG10994 | C38: Mr | D38: MUTHUKUMARAVEL K | E38: =CONCATENATE(C38,".",D38) -> Mr.MUTHUKUMARAVEL K | F38: Agricultural Engineering | G38: Assistant Professor Level I | H38: muthukumaravelk@bitsathy.ac.in | I38: =IFERROR(__xludf.DUMMYFUNCTION("QUERY(IMPORTRANGE(""https://docs.google.com/spreadsheets/d/1WWWnL0uEco2fCr2WvkXmt_9_Ox7wL_0CmzT8iuRp0aQ/edit?gid=1871111119#gid=1871111119"",""Details!A:X""),""SELECT Col8, Col9, Col10, Col11, Col12, Col13, Col14 WHERE Col2='""&B38&""'"",0)"),1.0) -> 1 | J38: =IFERROR(__xludf.DUMMYFUNCTION("""COMPUTED_VALUE"""),0.0) -> 0 | K38: =IFERROR(__xludf.DUMMYFUNCTION("""COMPUTED_VALUE"""),1.0) -> 1 | L38: =IFERROR(__xludf.DUMMYFUNCTION("""COMPUTED_VALUE"""),0.0) -> 0 | M38: =IFERROR(__xludf.DUMMYFUNCTION("""COMPUTED_VALUE"""),"Working") -> Working | N38: =IFERROR(__xludf.DUMMYFUNCTION("""COMPUTED_VALUE"""),"CORRECT") -> CORRECT | O38: =IFERROR(__xludf.DUMMYFUNCTION("""COMPUTED_VALUE"""),"CORRECT") -> CORRECT | P38: =IF(K38>I38,"Extra Theory Load Alloted","") | Q38: =IF(L38>J38,"Extra Lab Load Alloted","")
A39: 38 | B39: AG11049 | C39: Dr | D39: PRAVEEN KUMAR D | E39: =CONCATENATE(C39,".",D39) -> Dr.PRAVEEN KUMAR D | F39: Agricultural Engineering | G39: Assistant Professor Level II | H39: praveenkumard@bitsathy.ac.in | I39: =IFERROR(__xludf.DUMMYFUNCTION("QUERY(IMPORTRANGE(""https://docs.google.com/spreadsheets/d/1WWWnL0uEco2fCr2WvkXmt_9_Ox7wL_0CmzT8iuRp0aQ/edit?gid=1871111119#gid=1871111119"",""Details!A:X""),""SELECT Col8, Col9, Col10, Col11, Col12, Col13, Col14 WHERE Col2='""&B39&""'"",0)"),2.0) -> 2 | J39: =IFERROR(__xludf.DUMMYFUNCTION("""COMPUTED_VALUE"""),2.0) -> 2 | K39: =IFERROR(__xludf.DUMMYFUNCTION("""COMPUTED_VALUE"""),2.0) -> 2 | L39: =IFERROR(__xludf.DUMMYFUNCTION("""COMPUTED_VALUE"""),1.0) -> 1 | M39: =IFERROR(__xludf.DUMMYFUNCTION("""COMPUTED_VALUE"""),"Working") -> Working | N39: =IFERROR(__xludf.DUMMYFUNCTION("""COMPUTED_VALUE"""),"CORRECT") -> CORRECT | O39: =IFERROR(__xludf.DUMMYFUNCTION("""COMPUTED_VALUE"""),"LOAD PENDING") -> LOAD PENDING | P39: =IF(K39>I39,"Extra Theory Load Alloted","") | Q39: =IF(L39>J39,"Extra Lab Load Alloted","")
A40: 39 | B40: AG11083 | C40: Dr | D40: RAGHUL S | E40: =CONCATENATE(C40,".",D40) -> Dr.RAGHUL S | F40: Agricultural Engineering | G40: Assistant Professor Level I | H40: raghul@bitsathy.ac.in | I40: =IFERROR(__xludf.DUMMYFUNCTION("QUERY(IMPORTRANGE(""https://docs.google.com/spreadsheets/d/1WWWnL0uEco2fCr2WvkXmt_9_Ox7wL_0CmzT8iuRp0aQ/edit?gid=1871111119#gid=1871111119"",""Details!A:X""),""SELECT Col8, Col9, Col10, Col11, Col12, Col13, Col14 WHERE Col2='""&B40&""'"",0)"),2.0) -> 2 | J40: =IFERROR(__xludf.DUMMYFUNCTION("""COMPUTED_VALUE"""),2.0) -> 2 | K40: =IFERROR(__xludf.DUMMYFUNCTION("""COMPUTED_VALUE"""),1.0) -> 1 | L40: =IFERROR(__xludf.DUMMYFUNCTION("""COMPUTED_VALUE"""),2.0) -> 2 | M40: =IFERROR(__xludf.DUMMYFUNCTION("""COMPUTED_VALUE"""),"Working") -> Working | N40: =IFERROR(__xludf.DUMMYFUNCTION("""COMPUTED_VALUE"""),"LOAD PENDING") -> LOAD PENDING | O40: =IFERROR(__xludf.DUMMYFUNCTION("""COMPUTED_VALUE"""),"CORRECT") -> CORRECT | P40: =IF(K40>I40,"Extra Theory Load Alloted","") | Q40: =IF(L40>J40,"Extra Lab Load Alloted","")
...

Sheet AGRI
A1: Sl No | B1: Dept. | C1: Semester | D1: Course Type | E1: Course Code | F1: Course Name | G1: Course Nature | H1: L | I1: T | J1: P | K1: C | L1: Faculty ID (ME1880) | M1: Faculty Name | N1: Mail ID
A2: {=SEQUENCE(COUNTA(B2:B31),1)} -> 1 | B2: AGRI | C2: S2 | D2: CORE | E2: 22MA201 | F2: ENGINEERING MATHEMATICS II | G2: THEORY | H2: 3 | I2: 1 | J2: 0 | K2: 4 | L2: MA10071 | M2: =IFNA(VLOOKUP(L2,'Faculty Details'!$B:$H,4,0),"") -> Mrs.PREETHA R | N2: =IFNA(VLOOKUP(L2,'Faculty Details'!$B:$H,7,0),"") -> preetha@bitsathy.ac.in
A3: 2 | B3: AGRI | C3: S2 | D3: CORE | E3: 22PH202 | F3: ELECTROMAGNETISM AND MODERN PHYSICS | G3: THEORY WITH LAB | H3: 2 | I3: 0 | J3: 2 | K3: 3 | L3: PH11015 | M3: =IFNA(VLOOKUP(L3,'Faculty Details'!$B:$H,4,0),"") -> Dr.GOPI G | N3: =IFNA(VLOOKUP(L3,'Faculty Details'!$B:$H,7,0),"") -> gopi@bitsathy.ac.in
A4: 3 | B4: AGRI | C4: S2 | D4: CORE | E4: 22CH203 | F4: ENGINEERING CHEMISTRY II | G4: THEORY WITH LAB | H4: 2 | I4: 0 | J4: 2 | K4: 3 | L4: CH11057 | M4: =IFNA(VLOOKUP(L4,'Faculty Details'!$B:$H,4,0),"") -> Dr.KARUPPUSAMY S | N4: =IFNA(VLOOKUP(L4,'Faculty Details'!$B:$H,7,0),"") -> karuppusamys@bitsathy.ac.in
A5: 4 | B5: AGRI | C5: S2 | D5: CORE | E5: 22GE002 | F5: COMPUTATIONAL PROBLEM SOLVING | G5: THEORY | H5: 3 | I5: 0 | J5: 0 | K5: 3 | L5: CS11119 | M5: =IFNA(VLOOKUP(L5,'Faculty Details'!$B:$H,4,0),"") -> Ms.PARKAVI S | N5: =IFNA(VLOOKUP(L5,'Faculty Details'!$B:$H,7,0),"") -> parkavi@bitsathy.ac.in
A6: 5 | B6: AGRI | C6: S2 | D6: CORE | E6: 22GE004 | F6: BASICS OF ELECTRONICS ENGINEERING | G6: THEORY WITH LAB | H6: 2 | I6: 0 | J6: 2 | K6: 3 | L6: EC11131 | M6: =IFNA(VLOOKUP(L6,'Faculty Details'!$B:$H,4,0),"") -> Dr.SANKARANANTH S | N6: =IFNA(VLOOKUP(L6,'Faculty Details'!$B:$H,7,0),"") -> sankarananth@bitsathy.ac.in
A7: 6 | B7: AGRI | C7: S2 | D7: CORE | E7: 22HS002 | F7: STARTUP MANAGEMENT | G7: LAB | H7: 1 | I7: 0 | J7: 2 | K7: 2 | L7: AG11083 | M7: =IFNA(VLOOKUP(L7,'Faculty Details'!$B:$H,4,0),"") -> Dr.RAGHUL S | N7: =IFNA(VLOOKUP(L7,'Faculty Details'!$B:$H,7,0),"") -> raghul@bitsathy.ac.in
A8: 7 | B8: AGRI | C8: S2 | D8: CORE | E8: 22HS006 | F8: தமிழரும் ததொழில்நுட்பமும்/TAMILS AND TECHNOLOGY | G8: LAB | H8: 1 | I8: 0 | J8: 0 | K8: 1 | L8: HU11085 | M8: =IFNA(VLOOKUP(L8,'Faculty Details'!$B:$H,4,0),"") -> Dr.SAGUNTHALA DEVI P | N8: =IFNA(VLOOKUP(L8,'Faculty Details'!$B:$H,7,0),"") -> sagunthaladevi@bitsathy.ac.in
A9: 8 | B9: AGRI | C9: S2 | D9: CORE | E9: 22HS009 | F9: COCURRICULAR AND EXTRACURRICULAR ACTIVITIES
A10: 9 | B10: AGRI | C10: S2 | D10: LANGUAGE ELECTIVE | E10: 22HS201 | F10: COMMUNICATIVE ENGLISH II | G10: LAB | H10: 1 | I10: 0 | J10: 2 | K10: 2 | L10: HU11011 | M10: =IFNA(VLOOKUP(L10,'Faculty Details'!$B:$H,4,0),"") -> Dr.AJAI A | N10: =IFNA(VLOOKUP(L10,'Faculty Details'!$B:$H,7,0),"") -> ajai@bitsathy.ac.in
A11: 10 | B11: AGRI | C11: S4 | D11: CORE | E11: 22AG401 | F11: CROP PRODUCTION TECHNOLOGY | G11: THEORY WITH LAB | H11: 3 | I11: 0 | J11: 2 | K11: 4 | L11: AG11083 | M11: =IFNA(VLOOKUP(L11,'Faculty Details'!$B:$H,4,0),"") -> Dr.RAGHUL S | N11: =IFNA(VLOOKUP(L11,'Faculty Details'!$B:$H,7,0),"") -> raghul@bitsathy.ac.in
A12: 11 | B12: AGRI | C12: S4 | D12: CORE | E12: 22AG402 | F12: HEAT AND MASS TRANSFER | G12: THEORY WITH LAB | H12: 3 | I12: 0 | J12: 2 | K12: 4 | L12: AG10172 | M12: =IFNA(VLOOKUP(L12,'Faculty Details'!$B:$H,4,0),"") -> Dr.VINOTH KUMAR J | N12: =IFNA(VLOOKUP(L12,'Faculty Details'!$B:$H,7,0),"") -> vinothkumar@bitsathy.ac.in
A13: 12 | B13: AGRI | C13: S4 | D13: CORE | E13: 22AG403 | F13: STRENGTH OF MATERIALS | G13: THEORY | H13: 2 | I13: 1 | J13: 2 | K13: 4 | L13: MC10299 | M13: =IFNA(VLOOKUP(L13,'Faculty Details'!$B:$H,4,0),"") -> Mr.VIGNESH S | N13: =IFNA(VLOOKUP(L13,'Faculty Details'!$B:$H,7,0),"") -> vignesh@bitsathy.ac.in
A14: 13 | B14: AGRI | C14: S4 | D14: CORE | E14: 22AG403 | F14: STRENGTH OF MATERIALS | G14: LAB | H14: 2 | I14: 1 | J14: 2 | K14: 4 | L14: MC10299 | M14: =IFNA(VLOOKUP(L14,'Faculty Details'!$B:$H,4,0),"") -> Mr.VIGNESH S | N14: =IFNA(VLOOKUP(L14,'Faculty Details'!$B:$H,7,0),"") -> vignesh@bitsathy.ac.in
A15: 14 | B15: AGRI | C15: S4 | D15: CORE | E15: 22AG404 | F15: THEORY OF MACHINES | G15: THEORY WITH LAB | H15: 3 | I15: 0 | J15: 2 | K15: 4 | L15: AG1312 | M15: =IFNA(VLOOKUP(L15,'Faculty Details'!$B:$H,4,0),"") -> Dr.UVARAJA V C | N15: =IFNA(VLOOKUP(L15,'Faculty Details'!$B:$H,7,0),"") -> uvarajavc@bitsathy.ac.in
A16: 15 | B16: AGRI | C16: S4 | D16: CORE | E16: 22AG405 | F16: HYDROLOGY | G16: THEORY | H16: 3 | I16: 1 | J16: 0 | K16: 4 | L16: AG10092 | M16: =IFNA(VLOOKUP(L16,'Faculty Details'!$B:$H,4,0),"") -> Dr.VASUDEVAN M | N16: =IFNA(VLOOKUP(L16,'Faculty Details'!$B:$H,7,0),"") -> vasudevan@bitsathy.ac.in
A17: 16 | B17: AGRI | C17: S4 | D17: ELECTIVE 1 | E17: 22AG040 | F17: TECHNOLOGY OF SEED PROCESSING | G17: THEORY | H17: 3 | I17: 0 | J17: 0 | K17: 3 | L17: AG10895 | M17: =IFNA(VLOOKUP(L17,'Faculty Details'!$B:$H,4,0),"") -> Ms.ANANTHI D | N17: =IFNA(VLOOKUP(L17,'Faculty Details'!$B:$H,7,0),"") -> ananthid@bitsathy.ac.in
A18: 17 | B18: AGRI | C18: S4 | D18: CORE | E18: 22HS007 | F18: ENVIRONMENTAL SCIENCE | G18: LAB | H18: 2 | I18: 0 | J18: 0 | K18: 2 | L18: CH1558 | M18: =IFNA(VLOOKUP(L18,'Faculty Details'!$B:$H,4,0),"") -> Dr.PRAVEENA R | N18: =IFNA(VLOOKUP(L18,'Faculty Details'!$B:$H,7,0),"") -> praveenar@bitsathy.ac.in
A19: 18 | B19: AGRI | C19: S4 | D19: CORE | E19: 22HS008 | F19: ADVANCED ENGLISH AND TECHNICAL EXPRESSION | G19: LAB | H19: 0 | I19: 0 | J19: 2 | K19: 1 | L19: HU11011 | M19: =IFNA(VLOOKUP(L19,'Faculty Details'!$B:$H,4,0),"") -> Dr.AJAI A | N19: =IFNA(VLOOKUP(L19,'Faculty Details'!$B:$H,7,0),"") -> ajai@bitsathy.ac.in
A20: 19 | B20: AGRI | C20: S6 | D20: CORE | E20: 22AG601 | F20: FARM IMPLEMENTS | G20: THEORY WITH LAB | H20: 3 | I20: 0 | J20: 2 | K20: 4 | L20: AG11049 | M20: =IFNA(VLOOKUP(L20,'Faculty Details'!$B:$H,4,0),"") -> Dr.PRAVEEN KUMAR D | N20: =IFNA(VLOOKUP(L20,'Faculty Details'!$B:$H,7,0),"") -> praveenkumard@bitsathy.ac.in
A21: 20 | B21: AGRI | C21: S6 | D21: CORE | E21: 22AG602 | F21: POST HARVEST TECHNOLOGY | G21: THEORY | H21: 3 | I21: 0 | J21: 2 | K21: 4 | L21: AG10503 | M21: =IFNA(VLOOKUP(L21,'Faculty Details'!$B:$H,4,0),"") -> Dr.CHELLADURAI V | N21: =IFNA(VLOOKUP(L21,'Faculty Details'!$B:$H,7,0),"") -> chelladurai@bitsathy.ac.in
... A29: 28 | B29: AGRI | C29: S6 | D29: HONOURS | E29: 22AGH22 | F29: COGENERATION AND WASTE HEAT RECOVERY SYSTEMS | G29: THEORY | H29: 3 | I29: 0 | J29: 0 | K29: 3 | L29: AG11178 | M29: =IFNA(VLOOKUP(L29,'Faculty Details'!$B:$H,4,0),"") -> Ms.SNEKHA A R | N29: =IFNA(VLOOKUP(L29,'Faculty Details'!$B:$H,7,0),"") -> snekhaar@bitsathy.ac.in
A30: 29 | B30: AGRI | C30: S6 | D30: MINI PROJECT | E30: 22AG607 | F30: MINI PROJECT II | G30: LAB | H30: 0 | I30: 0 | J30: 2 | K30: 1 | M30: =IFNA(VLOOKUP(L30,'Faculty Details'!$B:$H,4,0),"") | N30: =IFNA(VLOOKUP(L30,'Faculty Details'!$B:$H,7,0),"")
A31: 30 | B31: AGRI | C31: S8 | D31: PROJECT | E31: 22AG801 | F31: PROJECT WORK II | G31: LAB | H31: 0 | I31: 0 | J31: 18 | K31: 9 | M31: =IFNA(VLOOKUP(L31,'Faculty Details'!$B:$H,4,0),"") | N31: =IFNA(VLOOKUP(L31,'Faculty Details'!$B:$H,7,0),"")

Sheet AIDS
A1: Si No. | B1: Dept. | C1: Semester | D1: Course Type | E1: Course Code | F1: Course Name | G1: Course Nature | H1: L | I1: T | J1: P | K1: C | L1: Faculty ID (ME1880) | M1: Faculty Name | N1: Mail ID
